Workbook
Name AireA: Feuil1!$E$16
Name As: Feuil1!$O$26
Name Av: Feuil1!$E$20
Name Avmin: Feuil1!$J$36
Name b: Feuil1!$E$12
Name bb: Feuil1!$E$27
Name beff_1: Feuil1!$O$4
Name beff_a: Feuil1!$O$5
Name bm: Feuil1!$E$32
Name bt: Feuil1!$E$28
Name c_z: Feuil1!$E$41
Name d: Feuil1!$E$6
Name dsc: Connexion!$D$4
Name dw: Feuil1!$E$19
Name e_s: Feuil1!$E$40
Name ebac: Feuil1!$E$26
Name Ecm: Feuil1!$J$9
Name Eta: Feuil1!$J$35
Name Ey: Feuil1!$J$6
Name Fck: Feuil1!$J$7
Name Fcm: Feuil1!$J$10
Name Fsk: Feuil1!$J$8
Name Fusc: Connexion!$D$6
Name Fy: Feuil1!$J$4
Name fybac: Feuil1!$E$30
Name g: Feuil1!$J$28
Name GammaC: Feuil1!$J$16
Name GammaG: Feuil1!$J$20
Name GammaM0: Feuil1!$J$14
Name GammaM1: Feuil1!$J$15
Name GammaQ: Feuil1!$J$21
Name GammaS: Feuil1!$J$17
Name GammaV: Feuil1!$J$18
Name hbac: Feuil1!$E$25
Name hsc: Connexion!$D$5
Name Ht: Feuil1!$E$11
Name hw: Feuil1!$E$18
Name kC: Feuil1!$O$53
Name La: Feuil1!$E$5
Name Le: Connexion!$H$60
Name Le_1: Feuil1!$O$7
Name Le_a: Feuil1!$O$8
Name LL: Feuil1!$E$4
Name MplaRd: Connexion!$M$78
Name MplRd_1: Feuil1!$O$19
Name MplRd_app: Feuil1!$O$37
Name mubac: Feuil1!$E$31
Name Na: Feuil1!$O$15
Name Nc: Feuil1!$O$14
Name Nf: Feuil1!$O$29
Name non: Feuil1!$T$3
Name Nr: Feuil1!$O$30
Name Ns: Feuil1!$O$25
Name Nu: Feuil1!$J$5
Name Nw: Feuil1!$O$31
Name oui: Feuil1!$T$2
Name p_1: Feuil1!$O$40
Name p_w: Feuil1!$R$40
Name PhiS: Feuil1!$E$39
Name PRd_dp: Connexion!$D$12

Sheet Feuil1
D2: Poutre | I2: Matériaux | N2: Largeurs participantes | T2: oui
T3: non
D4: Portee principale | E4: 10 | F4: m | I4: Fy | J4: 355 | K4: MPa | N4: Mi portée | O4: =MIN(d,Le_1/8*2) -> 2.125 | P4: m
D5: Portee console | E5: 3 | F5: m | I5: Nu | J5: 0.3 | N5: Appui | O5: =MIN(2*Le_a/8,d) -> 1.5 | P5: m
D6: Entraxe solives | E6: 2.5 | F6: m | I6: Ey | J6: 210000 | K6: MPa
I7: Fck | J7: 35 | K7: MPa | N7: Le mi portée | O7: =0.85*LL -> 8.5 | P7: m
D8: Profilé | I8: Fsk | J8: 500 | K8: MPa | N8: Le appui | O8: =2*La -> 6 | P8: m | Q8: =Le_a/8 -> 0.75
I9: Ecm | J9: =22*(Fcm/10)^0.3 -> 34.077146 | K9: GPa
E10: IPE360 | I10: Fcm | J10: =Fck+8 -> 43 | K10: MPa
D11: Ht | E11: 360 | F11: mm
D12: b | E12: 170 | F12: mm | I12: Coef. partiels | N12: Propriétés plastiques mi travée | U12: Vérifications
D13: tf | E13: 12.7 | F13: mm
D14: tw | E14: 8 | F14: mm | I14: GammaM0 | J14: 1 | N14: Nc | O14: =0.85*beff_1*tc*Fck/GammaC -> 3034.5 | P14: kN | U14: Flexion | V14: Sans prise en compte du degré de connexion
D15: rc | E15: 18 | F15: mm | I15: GammaM1 | J15: 1.1 | N15: Na | O15: =(AireA*Fy/1000)/GammaM0 -> 2581.888 | P15: kN
D16: Aa | E16: =b*tf*2+(Ht-2*tf)*tw+(4-PI())*rr^2 -> 7272.924 | F16: mm2 | I16: GammaC | J16: 1.5
E17: =AireA/100 -> 72.72924 | F17: cm2 | I17: GammaS | J17: 1.15 | N17: zn | O17: =tc*Na/Nc -> 61.260813 | P17: mm | W17: ELU 1 | Y17: ELU 2 | AA17: ELU 3
D18: hw | E18: =Ht-2*tf -> 334.6 | F18: mm | I18: GammaV | J18: 1.25 | V18: Flexion | W18: M>0 | X18: M<0 | Y18: M>0 | Z18: M<0 | AA18: M>0 | AB18: M<0
D19: dw | E19: =hw-2*rr -> 298.6 | F19: mm | N19: MplRd | O19: =Na*(Ht/2-zn/2+td)/1000 -> 721.301 | P19: kNm | Q19: (vrai pour Nc>Na) | V19: Travée console | X19: =ABS(MIN(Q64:Q74))/MplRd_app -> 0.80365439 | Z19: =ABS(MIN(S64:S74))/MplRd_app -> 0.16615603 | AB19: =ABS(MIN(U64:U74))/MplRd_app -> 0.80365439
D20: Av | E20: =(2*rr+tw)*tf+(Ht-2*tf)*tw+(4-PI())*rr^2 -> 3513.724 | F20: mm2 | I20: GammaG | J20: 1.35 | V20: Travée 2 | W20: =MAX(Q75:Q95)/MplRd_1 -> 0.086080605 | X20: =ABS(MIN(Q75:Q95))/MplRd_app -> 0.80365439 | Y20: =MAX(S75:S95)/MplRd_1 -> 1.2620142 | Z20: =ABS(MIN(S75:S95))/MplRd_app -> 0.16615603 | AA20: =MAX(U75:U95)/MplRd_1 -> 1.0853388 | AB20: =ABS(MIN(U75:U95))/MplRd_app -> 0.80365439
D21: Wpl | E21: 1019 | F21: cm3 | I21: GammaQ | J21: 1.5
N22: Propriétés plastiques sur appui | V22: Enveloppe | W22: M>0 | X22: M<0
D23: Bac | V23: Travée console | X23: =MAX(X19,Z19,AB19) -> 0.80365439
I24: Divers | N24: Na | O24: =(AireA*Fy/1000)/GammaM0 -> 2581.888 | P24: kN | V24: Travée 2 | W24: =MAX(W20,Y20,AA20) -> 1.2620142 | X24: =MAX(X20,Z20,AB20) -> 0.80365439
D25: hp | E25: 58 | F25: mm | N25: Ns | O25: =(As*Fsk/1000)/GammaS -> 728.48525 | P25: kN
D26: e | E26: 207 | F26: mm | I26: RhoA | J26: 7850 | K26: kg/m3 | N26: As | O26: =O27*PI()*PhiS^2/4 -> 1675.5161 | P26: mm2 | V26: Avec prise en compte degre connexion
D27: bb | E27: 62 | F27: mm | I27: RhoC | J27: 2500 | K27: kg/m3 | N27: Nombre armatures | O27: =beff_a/e_s*1000 -> 8.3333333 | V27: MplRd | W27: =Connexion!D74 -> 612.8023 | X27: =Connexion!E74 -> 626.00933 | Y27: =Connexion!F74 -> 640.27285
D28: bt | E28: 101 | F28: mm | I28: g | J28: 9.81 | K28: m/s2 | V28: MEd | W28: =MAX(Q75:Q95) -> 62.090027 | X28: =MAX(S75:S95) -> 910.29211 | Y28: =MAX(U75:U95) -> 782.85593
D29: t | E29: 0.75 | F29: mm | N29: Nf | O29: =b*tf*Fy/GammaM0/1000 -> 766.445 | P29: kN | W29: =W28/W27 -> 0.10132147 | X29: =X28/X27 -> 1.4541191 | Y29: =Y28/Y27 -> 1.2226911
D30: f | E30: 355 | F30: MPa | N30: Nr | O30: =(Na-2*Nf-Nw)/2 -> 100.48701 | P30: kN
D31: mu | E31: 8.53 | F31: kg/m2 | N31: Nw | O31: =dw*tw*Fy/1000/GammaM0 -> 848.024 | P31: kN
D32: bm | E32: =(bb+bt)/2 -> 81.5 | F32: mm | U32: Eff tranchant
I33: Résistance au cisaillement | N33: ANP dans la dalle ? | O33: =IF(Na<=Ns,uoi,non) -> non | W33: ELU 01 | X33: ELU 02 | Y33: ELU 03
D34: Dalle | N34: ANP dans la semelle ? | O34: =IF(AND(Ns<Na,Ns+Nf>Na-Nf),oui,non) -> non | P34: =O42 -> 524.81542 | V34: Console | W34: {=MAX(ABS(R64:R74))} -> 226.91476 | X34: {=MAX(ABS(T64:T74))} -> 46.914763 | Y34: {=MAX(ABS(V64:V74))} -> 226.91476
I35: Eta | J35: 1.2 | N35: ANP dans le congé ? | O35: =IF(AND(Ns>=Nw,Ns+Nf<Na-Nf),oui,non) -> non | V35: Travée | W35: {=MAX(ABS(R75:R95))} -> 112.22849 | X35: {=MAX(ABS(T75:T95))} -> 385.22849 | Y35: {=MAX(ABS(V75:V95))} -> 412.22849
D36: td | E36: 130 | F36: mm | I36: Avmin | J36: =hw*tw*Eta -> 3212.16 | K36: mm2 | N36: ANP dans l'âme droite ? | O36: =IF(Ns<Nw,oui,non) -> oui | P36: =R42 -> 423.5305
D37: tc | E37: =td-hbac -> 72 | F37: mm | I37: VplRd | J37: =MAX(Avmin,Av)*Fy/SQRT(3)/GammaM0/1000 -> 720.17057 | K37: kN | N37: MPlRd | O37: {=SUM(IF(O33:O36=oui,P33:P36,0))} -> 423.5305 | P37: kNm | V37: Critère | W37: ELU 01 | X37: ELU 02 | Y37: ELU 03
D38: Armatures | V38: Console | W38: =W34/VplRd -> 0.31508475 | X38: =X34/VplRd -> 0.06514396 | Y38: =Y34/VplRd -> 0.31508475
D39: Diamètre | E39: 16 | F39: mm | N39: Cas ANP dans la semelle | R39: Cas ANP dans l'âme | V39: Travée | W39: =W35/VplRd -> 0.15583598 | X39: =X35/VplRd -> 0.53491284 | Y39: =Y35/VplRd -> 0.57240396
D40: Entraxe | E40: 180 | F40: mm | N40: p | O40: =(Na-Ns)/2/Nf -> 1.2090905 | Q40: p | R40: =0.5-0.5*Ns/Nw -> 0.070480757
D41: Enrobage | E41: 20 | F41: mm | V41: Enveloppe
...

Sheet Connexion
C4: diametre | D4: 19 | E4: mm
C5: hauteur | D5: 100 | E5: mm
C6: fu | D6: 450 | E6: MPa
C9: PRd dalle pleine
C10: PRda | D10: =0.8*Fusc*PI()*dsc^2/4000/GammaV -> 81.656276 | E10: kN
C11: PRdc | D11: =0.29*dsc^2*SQRT(Fck*Ecm*1000)/GammaV/1000 -> 91.466238 | E11: kN
C12: PRd | D12: =MIN(PRda,PRdc) -> 81.656276 | E12: kN
C14: Coef de réduction
C15: nr | D15: kt | E15: ktmax | F15: kt
C16: 1 | D16: =0.7/SQRT(C16)*bm/hbac*(hsc/hbac-1) -> 0.71227705 | E16: 0.75 | F16: =MIN(D16:E16) -> 0.71227705
C17: 2 | D17: =0.7/SQRT(C17)*bm/hbac*(hsc/hbac-1) -> 0.50365593 | E17: 0.6 | F17: =MIN(D17:E17) -> 0.50365593
C20: PRd dalle mixte
C21: nr | D21: PRd
C22: 1 | D22: =F16*PRd_dp -> 58.161892 | E22: kN
C23: 2 | D23: =F17*PRd_dp -> 41.126668 | E23: kN
C27: Nombre de nervures en consoles
D28: =(La/ebac)*1000 -> 14.492754
D29: =INT(D28) -> 14
C30: Degré de connexion console
C31: nr | D31: d
C32: 1 | D32: =D29*D22/Ns -> 1.1177529 | F32: =Ns -> 728.48525 | G32: kN | H32: =D29*D22 -> 814.26648 | I32: =D28*D22 -> 842.92597
C33: 2 | D33: =D29*D23*C23/Ns -> 1.5807413
D35: Longueur | E35: nr | F35: PRd | G35: Prd/u
C36: Zone 1 | D36: 0 | E36: 2 | F36: =IF(E36=2,$D$23,$D$22) -> 41.126668 | G36: =F36*E36/(ebac/1000) -> 397.35911 | J36: =G36*D36 -> 0
C37: Zone 2 | D37: =LL-D36 -> 10 | E37: 2 | F37: =IF(E37=2,$D$23,$D$22) -> 41.126668 | G37: =F37*E37/(ebac/1000) -> 397.35911 | J37: =G37*D37 -> 3973.5911
C40: Longueur de chaque zone requise pour le moment négatif : L1
C41: Longueur restante : L2
D42: L1 | E42: L2
C43: Zone 1 | D43: =MIN(Ns/G36,D36) -> 0 | E43: =D36-D43 -> 0
C44: Zone 2 | D44: =IF(Ns/G36>D36,(Ns-G36*D36)/G37,0) -> 1.8333171 | E44: =D37-D44 -> 8.1666829
C48: Position du point de moment maxi
C50: ELU | D50: 1 | E50: 2 | F50: 3
C51: MEd | D51: =MAX(Feuil1!Q75:Q95) -> 62.090027 | E51: =MAX(Feuil1!S75:S95) -> 910.29211 | F51: =MAX(Feuil1!U75:U95) -> 782.85593
C52: x | D52: 7.1 | E52: 5 | F52: 5.3 | H52: 7
C53: RConnex G | D53: =($D$36-$D$43)*$G$36+(D52-$D$36-$D$44)*$G$37 -> 2092.7644 | E53: =($D$36-$D$43)*$G$36+(E52-$D$36-$D$44)*$G$37 -> 1258.3103 | F53: =($D$36-$D$43)*$G$36+(F52-$D$36-$D$44)*$G$37 -> 1377.518
C54: RConnex D | D54: =(LL-D52)*$G$37 -> 1152.3414 | E54: =(LL-E52)*$G$37 -> 1986.7956 | F54: =(LL-F52)*$G$37 -> 1867.5878
C55: RConnex | D55: =MIN(D53:D54) -> 1152.3414 | E55: =MIN(E53:E54) -> 1258.3103 | F55: =MIN(F53:F54) -> 1377.518
C57: Na | D57: =Feuil1!O24 -> 2581.888 | E57: kN
C58: Nc | D58: =Nc -> 3034.5 | E58: kN
C59: Eta | D59: =D55/MIN($D$57:$D$58) -> 0.44631735 | E59: =E55/MIN($D$57:$D$58) -> 0.48736053 | F59: =F55/MIN($D$57:$D$58) -> 0.53353129
...
