Workbook
Name A: Feuil1!$N$26
Name Ac: Feuil1!$D$50
Name b0Bac: Feuil1!$D$67
Name bAppMin: Feuil1!$D$38
Name BetaW: Feuil1!#REF!
Name bf: Feuil1!$D$7
Name bfs: Feuil1!$D$6
Name BinfBac: Feuil1!$D$63
Name BsupBac: Feuil1!$D$62
Name d_1: Feuil1!$D$30
Name d_2: Feuil1!$D$31
Name dApp: 'Section élastique'!$D$15
Name dbt: 'Section élastique'!$L$20
Name df: 'Section élastique'!$D$20
Name dp: 'Section élastique'!#REF!
Name dW: Feuil1!$D$10
Name E: Feuil1!$D$29
Name eBac: Feuil1!$D$61
Name Elan: Feuil1!#REF!
Name ElancementW: Feuil1!#REF!
Name EpsilonW: Feuil1!#REF!
Name Eta: Feuil1!#REF!
Name F_Q2: Feuil1!$I$8
Name Fu: Feuil1!$D$23
Name FyI: Feuil1!$D$21
Name FyPl: Feuil1!$D$22
Name FyS: Feuil1!$D$19
Name FyW: Feuil1!$D$20
Name g: Feuil1!$N$79
Name GammaG: Feuil1!$N$6
Name GammaM0: Feuil1!$N$8
Name GammaM1: Feuil1!$N$9
Name GammaM2: Feuil1!$N$11
Name GammaQ: Feuil1!$N$7
Name hb: Feuil1!$D$13
Name hBac: Feuil1!$D$60
Name Ht: Feuil1!$D$16
Name hw: Feuil1!$D$9
Name hwe: Feuil1!$N$46
Name hwP: Feuil1!$D$17
Name IncertieCM: Feuil1!$N$29
Name InertieY_MM4: Feuil1!$N$28
Name kcG: Feuil1!$W$6
Name kcI: Feuil1!$W$7
Name KhiLT: Feuil1!#REF!
Name KhiW: Feuil1!#REF!
Name kTau: Feuil1!#REF!
Name LambdaLT: Feuil1!#REF!
Name LambdaW: Feuil1!#REF!
Name listeNbAppuis: Param!$I$7:$I$10
Name LL: Feuil1!$D$27
Name MatriceRa: Param!$I$7:$J$10
Name Mcr: Feuil1!#REF!
Name MEd_Q1: Feuil1!$J$15
Name MEd_Q2: Feuil1!$J$17
Name MEd_U1: Feuil1!$J$23
Name MEd_U2: Feuil1!$J$25
Name MEdG: Feuil1!$J$13
Name MelRd: Feuil1!$Q$30
Name MplRd: Feuil1!$Q$61

Sheet Feuil1
D1: CAS Slim floor Acier
D2: SFS04 | E2: SAB
C4: Profilé IFB-A | H4: Charges | M4: Coefficients partiels
C6: bfs | D6: 160 | E6: mm | H6: G | I6: =D56 -> 11.121622 | J6: kN/m | M6: GammaG | N6: 1.35 | V6: kcg | W6: =(10-3*PI())/(12-3*PI()) -> 0.22336794
C7: bfi | D7: 300 | E7: mm | H7: Q1 | I7: =10*AVERAGE(D30:D31) -> 20 | J7: kN/m | M7: GammaQ | N7: 1.5 | V7: kcI | W7: =0.0151 -> 0.0151
C8: tf | D8: 22.5 | E8: mm | H8: Q2 | I8: 0 | J8: kN | M8: GammaM0 | N8: 1
C9: hw | D9: =hb-2*tf -> 315 | E9: mm | M9: GammaM1 | N9: 1
C10: dw | D10: =hb-2*tf-2*rr -> 261 | E10: mm | M10: Psi 0 | N10: 0.7
C11: tw | D11: 12.5 | E11: mm | M11: GammaM2 | N11: 1.25
C12: rc | D12: 27 | E12: mm | H12: Analyse
C13: hb | D13: 360 | E13: mm | H13: G | I13: MEd | J13: =qG*LL^2/8 -> 112.60643 | K13: kNm
C14: plat b | D14: 0 | E14: mm | I14: VEd | J14: =qG*LL/2 -> 50.0473 | K14: kN
C15: plat t | D15: 0 | E15: mm | H15: Q1 | I15: MEd | J15: =qQ_1*LL^2/8 -> 202.5 | K15: kNm | M15: Propriétés élastiques
C16: ha | D16: =hb -> 360 | E16: mm | I16: VEd | J16: =qQ_1*LL/2 -> 90 | K16: kN
C17: hwPrime | D17: =Ht-Pl_t-tf -> 337.5 | E17: mm | H17: Q2 | I17: MEd | J17: =F_Q2*LL/4 -> 0 | K17: kNm | N17: Ai | O17: zi | P17: Aizi | Q17: di | R17: Aidi2 | S17: Ii
I18: VEd | J18: =F_Q2/2 -> 0 | K18: kN | M18: fs | N18: =bfs*tf -> 3600 | O18: =hb-tf-tf/2 -> 326.25 | P18: =N18*O18 -> 1174500 | Q18: =O18-zG -> 204.39357 | R18: =N18*Q18^2 -> 1.5039623e+08 | S18: =bfs*tf^3/12 -> 151875
C19: FyS | D19: 420 | E19: MPa | M19: rs | N19: =(4-PI())*rr^2/2 -> 312.88948 | O19: =hb-2*tf-kcG*rr -> 308.96907 | P19: =N19*O19 -> 96673.17 | Q19: =O19-zG -> 187.11264 | R19: =N19*Q19^2 -> 10954617 | S19: =S21 -> 8024.7591
C20: Fyw | D20: =FyS -> 420 | E20: Mpa | M20: w | N20: =hw*tw -> 3937.5 | O20: =hw/2 -> 157.5 | P20: =N20*O20 -> 620156.25 | Q20: =O20-zG -> 35.64357 | R20: =N20*Q20^2 -> 5002452.3 | S20: =hw^3*tw/12 -> 32558203
C21: FyI | D21: =FyS -> 420 | E21: MPa | H21: Combinaisons | M21: ri | N21: =(4-PI())*rr^2/2 -> 312.88948 | O21: =kcG*rr -> 6.0309344 | P21: =N21*O21 -> 1887.0159 | Q21: =O21-zG -> -115.8255 | R21: =N21*Q21^2 -> 4197583 | S21: =kcI*rr^4 -> 8024.7591
C22: FyPl | D22: 345 | E22: MPa | M22: fi | N22: =bf*tf -> 6750 | O22: =-tf/2 -> -11.25 | P22: =N22*O22 -> -75937.5 | Q22: =O22-zG -> -133.10643 | R22: =N22*Q22^2 -> 1.1959192e+08 | S22: =bf*tf^3/12 -> 284765.62
C23: Fu | D23: 470 | E23: MPa | H23: ELU 01 | I23: MEd | J23: =GammaG*MEdG+GammaQ*(MEd_Q1+Psi_0*MEd_Q2) -> 455.76867 | K23: kNm | M23: Plat | N23: =Pl_b*Pl_t -> 0 | O23: =Ht-tf-Pl_t/2 -> 337.5 | P23: =N23*O23 -> 0 | Q23: =O23-zG -> 215.64357 | R23: =N23*Q23^2 -> 0 | S23: =Pl_b*Pl_t^3/12 -> 0
I24: VEd | J24: =GammaG*VEdG+GammaQ*(VEd_Q1+Psi_0*VEd_Q2) -> 202.56386 | K24: kN | N24: =SUM(N18:N23) -> 14913.279 | P24: =SUM(P18:P23) -> 1817278.9 | R24: =SUM(R18:R23) -> 2.9014281e+08 | S24: =SUM(S18:S23) -> 33010893
C25: Poutre | H25: ELU02 | I25: MEd | J25: =GammaG*MEdG+GammaQ*(Psi_0*MEd_Q1+MEd_Q2) -> 364.64367 | K25: kNm
I26: VEd | J26: =GammaG*VEdG+GammaQ*(Psi_0*VEd_Q1+VEd_Q2) -> 162.06386 | K26: kN | M26: A | N26: =N24 -> 14913.279 | O26: mm2 | U26: Av | V26: =SUM(N19:N21)+2*(2*rr+tw)*tf/2 -> 6059.529 | W26: mm2
C27: Portée | D27: 9 | E27: m | M27: zG | N27: =P24/A -> 121.85643 | O27: mm | P27: Welfs | Q27: =IncertieCM/(ABS(hb-tf-zG))*10 -> 1498.5548 | R27: cm3 | S27: =Q27*355/1000 -> 531.98694 | U27: masse linéique | V27: =7850*A/10^6 -> 117.06924 | W27: kg/m
M28: Inertie Y | N28: =SUM(R24:S24) -> 3.231537e+08 | O28: mm4 | P28: Welfi | Q28: =IncertieCM/(ABS(zG+tf))*10 -> 2238.582 | R28: cm3 | S28: =Q28*355/1000 -> 794.6966 | U28: masse poutre | V28: =V27*LL -> 1053.6232 | W28: kg
C29: E | D29: 210000 | E29: MPa | N29: =N28/10^4 -> 32315.37 | O29: cm4 | P29: WelpPl | R29: cm3 | S29: =Q29*355/1000 -> 0 | U29: Iz | V29: =Pl_t*Pl_b^3/12+hwP*tw^3/12+tf*bf^3/12+2*kcI*rr^4+(4-PI())*rr^2/2*(tw/2+kcG*rr)^2+tf*bfs^3/12 -> 58423172 | W29: mm4
C30: d1 | D30: 2 | E30: m | I30: qELU | J30: =GammaG*qG+GammaQ*(qQ_1) -> 45.01419 | K30: kN/m | P30: MelRd | Q30: =MIN(Q27*FyS,Q28*FyI)/1000/GammaM0 -> 629.393 | R30: kNm | V30: =V29/10^4 -> 5842.3172 | W30: cm4
C31: d2 | D31: 2 | E31: m | I31: FELU | J31: =Psi_0*GammaQ*F_Q2 -> 0 | K31: kN
M32: Propriétés plastiques
C33: Prédalle
N34: Ai | O34: fi | P34: Ni | Q34: zi | R34: Ni Bot | S34: NiTop
C35: Epaisseur | D35: 0 | E35: mm | I35: ELU | M35: Plat | N35: =N23 -> 0 | O35: =FyPl/GammaM0 -> 345 | P35: =N35*O35/1000 -> 0 | Q35: 0 | R35: =P42-P35 -> 6263.5772 | S35: =P35 -> 0
C36: Ep joint | D36: 0 | E36: mm | I36: GammaM | J36: =MEd_U1/MplRdRed -> 0.55731905 | M36: fs | N36: =N18 -> 3600 | O36: =FyS/GammaM0 -> 420 | P36: =N36*O36/1000 -> 1512 | Q36: =O18 -> 326.25 | R36: =R35-P36 -> 4751.5772 | S36: =S35+P36 -> 1512
I37: GammaV | J37: =VEd_U1/Q62 -> 0.13785878 | M37: rs | N37: =N19 -> 312.88948 | O37: =FyW/GammaM0 -> 420 | P37: =N37*O37/1000 -> 131.41358 | Q37: =O19 -> 308.96907 | R37: =R36-P37 -> 4620.1636 | S37: =S36+P37 -> 1643.4136
C38: bAppMin | D38: 50 | E38: mm | M38: w | N38: =N20 -> 3937.5 | O38: =FyW/GammaM0 -> 420 | P38: =N38*O38/1000 -> 1653.75 | Q38: =O20 -> 157.5 | R38: =R37-P38 -> 2966.4136 | S38: =S37+P38 -> 3297.1636
M39: ri | N39: =N21 -> 312.88948 | O39: =FyW/GammaM0 -> 420 | P39: =N39*O39/1000 -> 131.41358 | Q39: =O21 -> 6.0309344 | R39: =R38-P39 -> 2835 | S39: =S38+P39 -> 3428.5772
C40: Dalle | M40: fi | N40: =N22 -> 6750 | O40: =FyI/GammaM0 -> 420 | P40: =N40*O40/1000 -> 2835 | Q40: =O22 -> -11.25 | R40: =R39-P40 -> 0 | S40: =S39+P40 -> 6263.5772
C42: td | D42: 380 | E42: mm | N42: =SUM(N35:N40) -> 14913.279 | P42: =SUM(P35:P40) -> 6263.5772
C43: tc | D43: =td-hBac -> 160 | E43: mm
...

Sheet Section élastique
C2: Calcul élastique de la section
C4: Flexion globale
C6: Points | D6: zi | E6: 1/Wi | F6: SigmaXi | G6: GammaM
C7: 1 | D7: =hb -> 360 | E7: =1/(InertieY_MM4)*((zG-D7))*(10^3) -> -0.00073693592 | F7: =MEd_U1*E7*1000 -> -335.87231 | G7: =ABS(F7/(FyS/GammaM0)) -> 0.79969597 | K7: -113.47
C8: 2 | D8: =D7-tf -> 337.5 | E8: =1/(InertieY_MM4)*((zG-D8))*(10^3) -> -0.00066730961 | F8: =MEd_U1*E8*1000 -> -304.13882 | G8: =ABS(F8/(FyS/GammaM0)) -> 0.72414004 | K8: -138.15
C9: 3 | D9: =zG -> 121.85643 | E9: =1/(InertieY_MM4)*((zG-D9))*(10^3) -> 0 | F9: =MEd_U1*E9*1000 -> 0 | G9: =ABS(F9/(FyS/GammaM0)) -> 0 | K9: =1.35*K7+1.5*K8 -> -360.4095
C10: 4 | D10: =tf -> 22.5 | E10: =1/(InertieY_MM4)*((zG-D10))*(10^3) -> 0.00030745874 | F10: =MEd_U1*E10*1000 -> 140.13006 | G10: =ABS(F10/(FyS/GammaM0)) -> 0.33364301 | K10: =InertieY_MM4 -> 3.231537e+08
C11: 5 | D11: 0 | E11: =1/(InertieY_MM4)*((zG-D11))*(10^3) -> 0.00037708505 | F11: =MEd_U1*E11*1000 -> 171.86355 | G11: =ABS(F11/(FyS/GammaM0)) -> 0.40919894
C12: 6 | D12: =-Pl_t -> 0 | E12: =1/(InertieY_MM4)*((zG-D12))*(10^3) -> 0.00037708505 | F12: =MEd_U1*E12*1000 -> 171.86355 | G12: =ABS(F12/(FyS/GammaM0)) -> 0.40919894
C15: dApp | D15: =2/3*50 -> 33.333333
C17: Flexion locale
P18: Nw | Q18: =Feuil1!P38*PsiY -> 1634.7688
C19: Semelle
C20: df | D20: =(bf-tw)/2-rr -> 116.75 | E20: mm | G20: =bf -> 300 | K20: dbt | L20: =(bf-tw)/2-rr-dApp -> 83.416667 | M20: mm | P20: ANP dans l'âme
C21: SigmaY | D21: =qELU*df*6/tf^2/2 -> 31.143151 | E21: MPa | G21: =G20/2 -> 150 | H21: =G21-tw/2 -> 143.75 | I21: =H21-rr -> 116.75 | K21: qEd | L21: =qELU/2 -> 22.507095 | M21: kN/m | P21: p | Q21: =0.5+(Q26-Q31)/2/Q18 -> 0.095355622
H22: =tw -> 12.5 | I22: =rr -> 27 | P22: zANP | Q22: =pANP*hw -> 31.5 | R22: mm
K23: myBtEd | L23: =qEdFl*(dbt/1000) -> 1.8774668 | M23: kNm/m
D24: SigmaX | E24: SigmaY | F24: TauY | G24: VM | H24: GammaY | K24: myBtRd | L24: =1.2*tf^2/6*FyI/GammaM0/1000 -> 42.525 | M24: kNm/m
C25: Point 4 | D25: =F10 -> 140.13006 | E25: =+D21 -> 31.143151 | F25: 0 | G25: =SQRT(D25^2+E25^2-D25*E25+3*F25^2) -> 127.44504 | H25: =G25/(FyS/GammaM0) -> 0.30344058 | Q25: Ni | R25: zi | S25: di | T25: Nidi
C26: Point 4-5 | D26: =AVERAGE(D25,D27) -> 155.99681 | E26: 0 | F26: =3/2*qELU/tf/2 -> 1.500473 | G26: =SQRT(D26^2+E26^2-D26*E26+3*F26^2) -> 156.01846 | H26: =G26/(FyS/GammaM0) -> 0.37147251 | K26: Ratio | L26: =(L23/L24) -> 0.04414972 | P26: FSup | Q26: =Feuil1!P36 -> 1512 | R26: =Feuil1!O53 -> 326.25 | S26: =ABS(R26-$Q$22) -> 294.75 | T26: =Q26*S26/1000 -> 445.662
C27: Point 5 | D27: =F11 -> 171.86355 | E27: =-E25 -> -31.143151 | F27: 0 | G27: =SQRT(D27^2+E27^2-D27*E27+3*F27^2) -> 189.36565 | H27: =G27/(FyS/GammaM0) -> 0.4508706 | P27: Rsup | Q27: =Feuil1!P37 -> 131.41358 | R27: =Feuil1!O54 -> 308.96907 | S27: =ABS(R27-$Q$22) -> 277.46907 | T27: =Q27*S27/1000 -> 36.463203
C28: Point5 | D28: =F11 -> 171.86355 | E28: =#REF! -> #REF! | F28: 0 | G28: =SQRT(D28^2+E28^2-D28*E28+3*F28^2) -> #REF! | H28: =G28/(FyS/GammaM0) -> #REF! | K28: PsiY | L28: =(RatioFi-SQRT(RatioFi^2-16*RatioFi+16))/2/(RatioFi-2) -> 0.98852232 | P28: Wsup | Q28: =(1-Q21)*Q18 -> 1478.8844 | R28: =hw-(1-Q21)*hw/2 -> 172.51851 | S28: =ABS(R28-$Q$22) -> 141.01851 | T28: =Q28*S28/1000 -> 208.55007
C29: Point5-6 | D29: =AVERAGE(D28,D30) -> 171.86355 | E29: 0 | F29: =3/2*qELU/Pl_t/2 -> #DIV/0! | G29: =SQRT(D29^2+E29^2-D29*E29+3*F29^2) -> #DIV/0! | H29: =G29/(FyS/GammaM0) -> #DIV/0! | P29: Winf | Q29: =Q21*Q18 -> 155.88439 | R29: =Q21*hw/2 -> 15.01851 | S29: =ABS(R29-$Q$22) -> 16.48149 | T29: =Q29*S29/1000 -> 2.569207
C30: Point 6 | D30: =F12 -> 171.86355 | E30: =-E28 -> #REF! | F30: 0 | G30: =SQRT(D30^2+E30^2-D30*E30+3*F30^2) -> #REF! | H30: =G30/(FyS/GammaM0) -> #REF! | P30: Rinf | Q30: =Feuil1!P39 -> 131.41358 | R30: =Feuil1!O57 -> 6.0309344 | S30: =ABS(R30-$Q$22) -> 25.469066 | T30: =Q30*S30/1000 -> 3.3469811
P31: Finf | Q31: =Feuil1!P40 -> 2835 | R31: =Feuil1!O58 -> -11.25 | S31: =ABS(R31-$Q$22) -> 42.75 | T31: =Q31*S31/1000 -> 121.19625
T32: =SUM(T26:T31) -> 817.78772 | U32: kNm
S34: MplRd | T34: =T32 -> 817.78772 | U34: kNm
P36: Equilibre sup | Q36: =SUM(Q26:Q28) -> 3122.298
P37: Equilibre inf | Q37: =SUM(Q29:Q31) -> 3122.298

Sheet Param
C2: Oui
C3: Non
